Internal Server Error: /applications/
Traceback (most recent call last):
  File "/var/www/html/miuz/venv/lib/python3.8/site-packages/django/core/handlers/exception.py", line 55, in inner
    response = get_response(request)
  File "/var/www/html/miuz/venv/lib/python3.8/site-packages/django/core/handlers/base.py", line 197, in _get_response
    response = wrapped_callback(request, *callback_args, **callback_kwargs)
  File "/var/www/html/miuz/miuz/views.py", line 332, in admin_applicationfilter
    user_info = get_user_social_info(request)
NameError: name 'get_user_social_info' is not defined
Internal Server Error: /applications/
Traceback (most recent call last):
  File "/var/www/html/miuz/venv/lib/python3.8/site-packages/django/core/handlers/exception.py", line 55, in inner
    response = get_response(request)
  File "/var/www/html/miuz/venv/lib/python3.8/site-packages/django/core/handlers/base.py", line 197, in _get_response
    response = wrapped_callback(request, *callback_args, **callback_kwargs)
  File "/var/www/html/miuz/miuz/views.py", line 325, in admin_applicationfilter
    mid_name = request.POST.get('mid_name', request.user.mid_name)
  File "/var/www/html/miuz/venv/lib/python3.8/site-packages/django/utils/functional.py", line 268, in inner
    return func(_wrapped, *args)
AttributeError: 'User' object has no attribute 'mid_name'
Internal Server Error: /callback/
Traceback (most recent call last):
  File "/var/www/html/miuz/venv/lib/python3.8/site-packages/django/db/models/query.py", line 916, in get_or_create
    return self.get(**kwargs), False
  File "/var/www/html/miuz/venv/lib/python3.8/site-packages/django/db/models/query.py", line 637, in get
    raise self.model.DoesNotExist(
django.contrib.auth.models.User.DoesNotExist: User matching query does not exist.

During handling of the above exception, another exception occurred:

Traceback (most recent call last):
  File "/var/www/html/miuz/venv/lib/python3.8/site-packages/django/core/handlers/exception.py", line 55, in inner
    response = get_response(request)
  File "/var/www/html/miuz/venv/lib/python3.8/site-packages/django/core/handlers/base.py", line 197, in _get_response
    response = wrapped_callback(request, *callback_args, **callback_kwargs)
  File "/var/www/html/miuz/miuz/views.py", line 127, in callback
    user, created = User.objects.get_or_create(
  File "/var/www/html/miuz/venv/lib/python3.8/site-packages/django/db/models/manager.py", line 87, in manager_method
    return getattr(self.get_queryset(), name)(*args, **kwargs)
  File "/var/www/html/miuz/venv/lib/python3.8/site-packages/django/db/models/query.py", line 918, in get_or_create
    params = self._extract_model_params(defaults, **kwargs)
  File "/var/www/html/miuz/venv/lib/python3.8/site-packages/django/db/models/query.py", line 999, in _extract_model_params
    raise exceptions.FieldError(
django.core.exceptions.FieldError: Invalid field name(s) for model User: 'mid_name'.
Internal Server Error: /callback/
Traceback (most recent call last):
  File "/var/www/html/miuz/venv/lib/python3.8/site-packages/django/db/models/query.py", line 916, in get_or_create
    return self.get(**kwargs), False
  File "/var/www/html/miuz/venv/lib/python3.8/site-packages/django/db/models/query.py", line 637, in get
    raise self.model.DoesNotExist(
django.contrib.auth.models.User.DoesNotExist: User matching query does not exist.

During handling of the above exception, another exception occurred:

Traceback (most recent call last):
  File "/var/www/html/miuz/venv/lib/python3.8/site-packages/django/core/handlers/exception.py", line 55, in inner
    response = get_response(request)
  File "/var/www/html/miuz/venv/lib/python3.8/site-packages/django/core/handlers/base.py", line 197, in _get_response
    response = wrapped_callback(request, *callback_args, **callback_kwargs)
  File "/var/www/html/miuz/miuz/views.py", line 127, in callback
    user, created = User.objects.get_or_create(
  File "/var/www/html/miuz/venv/lib/python3.8/site-packages/django/db/models/manager.py", line 87, in manager_method
    return getattr(self.get_queryset(), name)(*args, **kwargs)
  File "/var/www/html/miuz/venv/lib/python3.8/site-packages/django/db/models/query.py", line 918, in get_or_create
    params = self._extract_model_params(defaults, **kwargs)
  File "/var/www/html/miuz/venv/lib/python3.8/site-packages/django/db/models/query.py", line 999, in _extract_model_params
    raise exceptions.FieldError(
django.core.exceptions.FieldError: Invalid field name(s) for model User: 'mid_name'.
Internal Server Error: /callback/
Traceback (most recent call last):
  File "/var/www/html/miuz/venv/lib/python3.8/site-packages/django/core/handlers/exception.py", line 55, in inner
    response = get_response(request)
  File "/var/www/html/miuz/venv/lib/python3.8/site-packages/django/core/handlers/base.py", line 197, in _get_response
    response = wrapped_callback(request, *callback_args, **callback_kwargs)
  File "/var/www/html/miuz/miuz/views.py", line 121, in callback
    print("OneID javobi:", json.dumps(user_info, indent=4))
NameError: name 'json' is not defined
Internal Server Error: /callback/
Traceback (most recent call last):
  File "/var/www/html/miuz/venv/lib/python3.8/site-packages/django/core/handlers/exception.py", line 55, in inner
    response = get_response(request)
  File "/var/www/html/miuz/venv/lib/python3.8/site-packages/django/core/handlers/base.py", line 197, in _get_response
    response = wrapped_callback(request, *callback_args, **callback_kwargs)
  File "/var/www/html/miuz/miuz/views.py", line 121, in callback
    print("OneID javobi:", json.dumps(user_info, indent=4))
NameError: name 'json' is not defined
Internal Server Error: /callback/
Traceback (most recent call last):
  File "/var/www/html/miuz/venv/lib/python3.8/site-packages/django/core/handlers/exception.py", line 55, in inner
    response = get_response(request)
  File "/var/www/html/miuz/venv/lib/python3.8/site-packages/django/core/handlers/base.py", line 197, in _get_response
    response = wrapped_callback(request, *callback_args, **callback_kwargs)
  File "/var/www/html/miuz/miuz/views.py", line 121, in callback
    print("OneID javobi:", json.dumps(user_info, indent=4))
NameError: name 'json' is not defined
Internal Server Error: /callback/
Traceback (most recent call last):
  File "/var/www/html/miuz/venv/lib/python3.8/site-packages/django/core/handlers/exception.py", line 55, in inner
    response = get_response(request)
  File "/var/www/html/miuz/venv/lib/python3.8/site-packages/django/core/handlers/base.py", line 197, in _get_response
    response = wrapped_callback(request, *callback_args, **callback_kwargs)
  File "/var/www/html/miuz/miuz/views.py", line 121, in callback
    print("OneID javobi:", json.dumps(user_info, indent=4))
NameError: name 'json' is not defined
Internal Server Error: /callback/
Traceback (most recent call last):
  File "/var/www/html/miuz/venv/lib/python3.8/site-packages/django/core/handlers/exception.py", line 55, in inner
    response = get_response(request)
  File "/var/www/html/miuz/venv/lib/python3.8/site-packages/django/core/handlers/base.py", line 197, in _get_response
    response = wrapped_callback(request, *callback_args, **callback_kwargs)
  File "/var/www/html/miuz/miuz/views.py", line 122, in callback
    print("OneID javobi:", json.dumps(user_info, indent=4))
UnboundLocalError: local variable 'user_info' referenced before assignment
Internal Server Error: /callback/
Traceback (most recent call last):
  File "/var/www/html/miuz/venv/lib/python3.8/site-packages/django/core/handlers/exception.py", line 55, in inner
    response = get_response(request)
  File "/var/www/html/miuz/venv/lib/python3.8/site-packages/django/core/handlers/base.py", line 197, in _get_response
    response = wrapped_callback(request, *callback_args, **callback_kwargs)
  File "/var/www/html/miuz/miuz/views.py", line 122, in callback
    print("OneID javobi:", json.dumps(user_info, indent=4))
UnboundLocalError: local variable 'user_info' referenced before assignment
Internal Server Error: /callback/
Traceback (most recent call last):
  File "/var/www/html/miuz/venv/lib/python3.8/site-packages/django/core/handlers/exception.py", line 55, in inner
    response = get_response(request)
  File "/var/www/html/miuz/venv/lib/python3.8/site-packages/django/core/handlers/base.py", line 197, in _get_response
    response = wrapped_callback(request, *callback_args, **callback_kwargs)
  File "/var/www/html/miuz/miuz/views.py", line 122, in callback
    print("OneID javobi:", json.dumps(user_info, indent=4))
UnboundLocalError: local variable 'user_info' referenced before assignment
Internal Server Error: /callback/
Traceback (most recent call last):
  File "/var/www/html/miuz/venv/lib/python3.8/site-packages/django/core/handlers/exception.py", line 55, in inner
    response = get_response(request)
  File "/var/www/html/miuz/venv/lib/python3.8/site-packages/django/core/handlers/base.py", line 197, in _get_response
    response = wrapped_callback(request, *callback_args, **callback_kwargs)
  File "/var/www/html/miuz/miuz/views.py", line 122, in callback
    print("OneID javobi:", json.dumps(user_info, indent=4))
UnboundLocalError: local variable 'user_info' referenced before assignment
Internal Server Error: /callback/
Traceback (most recent call last):
  File "/var/www/html/miuz/venv/lib/python3.8/site-packages/django/core/handlers/exception.py", line 55, in inner
    response = get_response(request)
  File "/var/www/html/miuz/venv/lib/python3.8/site-packages/django/core/handlers/base.py", line 197, in _get_response
    response = wrapped_callback(request, *callback_args, **callback_kwargs)
  File "/var/www/html/miuz/miuz/views.py", line 122, in callback
    print("OneID javobi:", json.dumps(user_info, indent=4))
UnboundLocalError: local variable 'user_info' referenced before assignment
Internal Server Error: /callback/
Traceback (most recent call last):
  File "/var/www/html/miuz/venv/lib/python3.8/site-packages/django/core/handlers/exception.py", line 55, in inner
    response = get_response(request)
  File "/var/www/html/miuz/venv/lib/python3.8/site-packages/django/core/handlers/base.py", line 197, in _get_response
    response = wrapped_callback(request, *callback_args, **callback_kwargs)
  File "/var/www/html/miuz/miuz/views.py", line 122, in callback
    print("OneID javobi:", json.dumps(user_info, indent=4))
UnboundLocalError: local variable 'user_info' referenced before assignment
Internal Server Error: /callback/
Traceback (most recent call last):
  File "/var/www/html/miuz/venv/lib/python3.8/site-packages/django/core/handlers/exception.py", line 55, in inner
    response = get_response(request)
  File "/var/www/html/miuz/venv/lib/python3.8/site-packages/django/core/handlers/base.py", line 197, in _get_response
    response = wrapped_callback(request, *callback_args, **callback_kwargs)
  File "/var/www/html/miuz/miuz/views.py", line 122, in callback
    print("OneID javobi:", json.dumps(user_info, indent=4))
UnboundLocalError: local variable 'user_info' referenced before assignment
Internal Server Error: /callback/
Traceback (most recent call last):
  File "/var/www/html/miuz/venv/lib/python3.8/site-packages/django/core/handlers/exception.py", line 55, in inner
    response = get_response(request)
  File "/var/www/html/miuz/venv/lib/python3.8/site-packages/django/core/handlers/base.py", line 197, in _get_response
    response = wrapped_callback(request, *callback_args, **callback_kwargs)
  File "/var/www/html/miuz/miuz/views.py", line 122, in callback
    print("OneID javobi:", json.dumps(user_info, indent=4))
UnboundLocalError: local variable 'user_info' referenced before assignment
Internal Server Error: /callback/
Traceback (most recent call last):
  File "/var/www/html/miuz/venv/lib/python3.8/site-packages/django/core/handlers/exception.py", line 55, in inner
    response = get_response(request)
  File "/var/www/html/miuz/venv/lib/python3.8/site-packages/django/core/handlers/base.py", line 197, in _get_response
    response = wrapped_callback(request, *callback_args, **callback_kwargs)
  File "/var/www/html/miuz/miuz/views.py", line 122, in callback
    print("OneID javobi:", json.dumps(user_info, indent=4))
UnboundLocalError: local variable 'user_info' referenced before assignment
Internal Server Error: /callback/
Traceback (most recent call last):
  File "/var/www/html/miuz/venv/lib/python3.8/site-packages/django/core/handlers/exception.py", line 55, in inner
    response = get_response(request)
  File "/var/www/html/miuz/venv/lib/python3.8/site-packages/django/core/handlers/base.py", line 197, in _get_response
    response = wrapped_callback(request, *callback_args, **callback_kwargs)
  File "/var/www/html/miuz/miuz/views.py", line 122, in callback
    print("OneID javobi:", json.dumps(user_info, indent=4))
UnboundLocalError: local variable 'user_info' referenced before assignment
Internal Server Error: /callback/
Traceback (most recent call last):
  File "/var/www/html/miuz/venv/lib/python3.8/site-packages/django/core/handlers/exception.py", line 55, in inner
    response = get_response(request)
  File "/var/www/html/miuz/venv/lib/python3.8/site-packages/django/core/handlers/base.py", line 197, in _get_response
    response = wrapped_callback(request, *callback_args, **callback_kwargs)
  File "/var/www/html/miuz/miuz/views.py", line 122, in callback
    print("OneID javobi:", json.dumps(user_info, indent=4))
UnboundLocalError: local variable 'user_info' referenced before assignment
Internal Server Error: /callback/
Traceback (most recent call last):
  File "/var/www/html/miuz/venv/lib/python3.8/site-packages/django/core/handlers/exception.py", line 55, in inner
    response = get_response(request)
  File "/var/www/html/miuz/venv/lib/python3.8/site-packages/django/core/handlers/base.py", line 197, in _get_response
    response = wrapped_callback(request, *callback_args, **callback_kwargs)
  File "/var/www/html/miuz/miuz/views.py", line 122, in callback
    print("OneID javobi:", json.dumps(user_info, indent=4))
UnboundLocalError: local variable 'user_info' referenced before assignment
Internal Server Error: /callback/
Traceback (most recent call last):
  File "/var/www/html/miuz/venv/lib/python3.8/site-packages/django/core/handlers/exception.py", line 55, in inner
    response = get_response(request)
  File "/var/www/html/miuz/venv/lib/python3.8/site-packages/django/core/handlers/base.py", line 197, in _get_response
    response = wrapped_callback(request, *callback_args, **callback_kwargs)
  File "/var/www/html/miuz/miuz/views.py", line 122, in callback
    print("OneID javobi:", json.dumps(user_info, indent=4))
UnboundLocalError: local variable 'user_info' referenced before assignment
Internal Server Error: /callback/
Traceback (most recent call last):
  File "/var/www/html/miuz/venv/lib/python3.8/site-packages/django/core/handlers/exception.py", line 55, in inner
    response = get_response(request)
  File "/var/www/html/miuz/venv/lib/python3.8/site-packages/django/core/handlers/base.py", line 197, in _get_response
    response = wrapped_callback(request, *callback_args, **callback_kwargs)
  File "/var/www/html/miuz/miuz/views.py", line 122, in callback
    print("OneID javobi:", json.dumps(user_info, indent=4))
UnboundLocalError: local variable 'user_info' referenced before assignment
Internal Server Error: /callback/
Traceback (most recent call last):
  File "/var/www/html/miuz/venv/lib/python3.8/site-packages/django/core/handlers/exception.py", line 55, in inner
    response = get_response(request)
  File "/var/www/html/miuz/venv/lib/python3.8/site-packages/django/core/handlers/base.py", line 197, in _get_response
    response = wrapped_callback(request, *callback_args, **callback_kwargs)
  File "/var/www/html/miuz/miuz/views.py", line 122, in callback
    print("OneID javobi:", json.dumps(user_info, indent=4))
UnboundLocalError: local variable 'user_info' referenced before assignment
Internal Server Error: /callback/
Traceback (most recent call last):
  File "/var/www/html/miuz/venv/lib/python3.8/site-packages/django/core/handlers/exception.py", line 55, in inner
    response = get_response(request)
  File "/var/www/html/miuz/venv/lib/python3.8/site-packages/django/core/handlers/base.py", line 197, in _get_response
    response = wrapped_callback(request, *callback_args, **callback_kwargs)
  File "/var/www/html/miuz/miuz/views.py", line 122, in callback
    print("OneID javobi:", json.dumps(user_info, indent=4))
UnboundLocalError: local variable 'user_info' referenced before assignment
Internal Server Error: /callback/
Traceback (most recent call last):
  File "/var/www/html/miuz/venv/lib/python3.8/site-packages/django/core/handlers/exception.py", line 55, in inner
    response = get_response(request)
  File "/var/www/html/miuz/venv/lib/python3.8/site-packages/django/core/handlers/base.py", line 197, in _get_response
    response = wrapped_callback(request, *callback_args, **callback_kwargs)
  File "/var/www/html/miuz/miuz/views.py", line 122, in callback
    print("OneID javobi:", json.dumps(user_info, indent=4))
UnboundLocalError: local variable 'user_info' referenced before assignment
Internal Server Error: /callback/
Traceback (most recent call last):
  File "/var/www/html/miuz/venv/lib/python3.8/site-packages/django/core/handlers/exception.py", line 55, in inner
    response = get_response(request)
  File "/var/www/html/miuz/venv/lib/python3.8/site-packages/django/core/handlers/base.py", line 197, in _get_response
    response = wrapped_callback(request, *callback_args, **callback_kwargs)
  File "/var/www/html/miuz/miuz/views.py", line 122, in callback
    print("OneID javobi:", json.dumps(user_info, indent=4))
UnboundLocalError: local variable 'user_info' referenced before assignment
Internal Server Error: /callback/
Traceback (most recent call last):
  File "/var/www/html/miuz/venv/lib/python3.8/site-packages/django/core/handlers/exception.py", line 55, in inner
    response = get_response(request)
  File "/var/www/html/miuz/venv/lib/python3.8/site-packages/django/core/handlers/base.py", line 197, in _get_response
    response = wrapped_callback(request, *callback_args, **callback_kwargs)
  File "/var/www/html/miuz/miuz/views.py", line 122, in callback
    if user_info_response.status_code == 200:
UnboundLocalError: local variable 'user_info' referenced before assignment
Internal Server Error: /callback/
Traceback (most recent call last):
  File "/var/www/html/miuz/venv/lib/python3.8/site-packages/django/core/handlers/exception.py", line 55, in inner
    response = get_response(request)
  File "/var/www/html/miuz/venv/lib/python3.8/site-packages/django/core/handlers/base.py", line 197, in _get_response
    response = wrapped_callback(request, *callback_args, **callback_kwargs)
  File "/var/www/html/miuz/miuz/views.py", line 122, in callback
    # Foydalanuvchi ma'lumotlarini olish
UnboundLocalError: local variable 'user_info' referenced before assignment
